{"trial_id": "00", "hyperparameters": {"space": [{"class_name": "Choice", "config": {"name": "dense_units", "default": 64, "conditions": [], "values": [64, 128, 256], "ordered": true}}, {"class_name": "Float", "config": {"name": "dropout_rate", "default": 0.2, "conditions": [], "min_value": 0.2, "max_value": 0.5, "step": 0.1, "sampling": "linear"}}, {"class_name": "Choice", "config": {"name": "learning_rate", "default": 0.0001, "conditions": [], "values": [0.0001, 0.001, 0.0005], "ordered": true}}], "values": {"dense_units": 256, "dropout_rate": 0.4, "learning_rate": 0.0005}}, "metrics": {"metrics": {}}, "score": null, "best_step": 0, "status": "FAILED", "message": "Traceback (most recent call last):\n  File \"/Users/diego.ferro/ma_ml_proyecto/venv/lib/python3.11/site-packages/keras_tuner/src/engine/base_tuner.py\", line 274, in _try_run_and_update_trial\n    self._run_and_update_trial(trial, *fit_args, **fit_kwargs)\n  File \"/Users/diego.ferro/ma_ml_proyecto/venv/lib/python3.11/site-packages/keras_tuner/src/engine/base_tuner.py\", line 239, in _run_and_update_trial\n    results = self.run_trial(trial, *fit_args, **fit_kwargs)\n              ^^^^^^^^^^^^^^^^^^^^^^^^^^^^^^^^^^^^^^^^^^^^^^\n  File \"/Users/diego.ferro/ma_ml_proyecto/venv/lib/python3.11/site-packages/keras_tuner/src/engine/tuner.py\", line 314, in run_trial\n    obj_value = self._build_and_fit_model(trial, *args, **copied_kwargs)\n                ^^^^^^^^^^^^^^^^^^^^^^^^^^^^^^^^^^^^^^^^^^^^^^^^^^^^^^^^\n  File \"/Users/diego.ferro/ma_ml_proyecto/venv/lib/python3.11/site-packages/keras_tuner/src/engine/tuner.py\", line 233, in _build_and_fit_model\n    results = self.hypermodel.fit(hp, model, *args, **kwargs)\n              ^^^^^^^^^^^^^^^^^^^^^^^^^^^^^^^^^^^^^^^^^^^^^^^\n  File \"/Users/diego.ferro/ma_ml_proyecto/venv/lib/python3.11/site-packages/keras_tuner/src/engine/hypermodel.py\", line 149, in fit\n    return model.fit(*args, **kwargs)\n           ^^^^^^^^^^^^^^^^^^^^^^^^^^\n  File \"/Users/diego.ferro/ma_ml_proyecto/venv/lib/python3.11/site-packages/keras/src/utils/traceback_utils.py\", line 70, in error_handler\n    raise e.with_traceback(filtered_tb) from None\n  File \"/var/folders/5v/6qhnzfvj3tq7qy7gh_0s5qtc0000gp/T/__autograph_generated_file_qbskhio.py\", line 18, in tf__train_function\n    raise\nValueError: in user code:\n\n    File \"/Users/diego.ferro/ma_ml_proyecto/venv/lib/python3.11/site-packages/keras/src/engine/training.py\", line 1338, in train_function  *\n        return step_function(self, iterator)\n    File \"/Users/diego.ferro/ma_ml_proyecto/venv/lib/python3.11/site-packages/keras/src/engine/training.py\", line 1322, in step_function  **\n        outputs = model.distribute_strategy.run(run_step, args=(data,))\n    File \"/Users/diego.ferro/ma_ml_proyecto/venv/lib/python3.11/site-packages/keras/src/engine/training.py\", line 1303, in run_step  **\n        outputs = model.train_step(data)\n    File \"/Users/diego.ferro/ma_ml_proyecto/venv/lib/python3.11/site-packages/keras/src/engine/training.py\", line 1080, in train_step\n        y_pred = self(x, training=True)\n    File \"/Users/diego.ferro/ma_ml_proyecto/venv/lib/python3.11/site-packages/keras/src/utils/traceback_utils.py\", line 70, in error_handler\n        raise e.with_traceback(filtered_tb) from None\n\n    ValueError: Exception encountered when calling layer 'stem_conv' (type Conv2D).\n    \n    Negative dimension size caused by subtracting 3 from 2 for '{{node model/stem_conv/Conv2D}} = Conv2D[T=DT_FLOAT, data_format=\"NHWC\", dilations=[1, 1, 1, 1], explicit_paddings=[], padding=\"VALID\", strides=[1, 2, 2, 1], use_cudnn_on_gpu=true](model/stem_conv_pad/Pad, model/stem_conv/Conv2D/ReadVariableOp)' with input shapes: [1,2,2,3], [3,3,3,32].\n    \n    Call arguments received by layer 'stem_conv' (type Conv2D):\n      \u2022 inputs=tf.Tensor(shape=(1, 2, 2, 3), dtype=float32)\n\n"}